<?xml version="1.0"?>
<robot xmlns:xacro="http://www.ros.org/wiki/xacro" name="dyros_assembly_gripper2">
  <xacro:macro name="dyros_assembly_gripper2" params="connected_to:='' ns:='' rpy:='0 0 0' xyz:='0 0 0' ">
    <xacro:unless value="${connected_to == ''}">
      <joint name="${ns}_hand_joint" type="fixed">
        <parent link="${connected_to}"/>
        <child link="${ns}_hand"/>
        <origin xyz="${xyz}" rpy="${rpy}"/>
      </joint>
    </xacro:unless>
    <link name="${ns}_hand">
      <visual>
        <origin xyz="0 0 0" rpy="-1.57 0 -1.57"/>
        <geometry>
          <mesh filename="package://assembly_env_description/meshes/gripper2_base.stl" scale="0.001 0.001 0.001"/>
        </geometry>
        <material name="white">
          <color rgba="0.9 0.9 0.9 0.75"/>
        </material>
      </visual>
      <collision>
        <origin xyz="0.017 0 0.029" rpy="0 0 0"/>
        <geometry>

          <box size="0.125 0.21 0.06"/>

        </geometry>
      </collision>
      <inertial>
        <mass value="0.55"/>
        <inertia ixx="0.0014362" ixy="0.000013" ixz="-0.0000278" iyy="0.00077" iyz="-0.0000000" izz="0.001039"/>
      </inertial>
    </link>      

    <joint name="${ns}_finger_right_joint" type="prismatic">
      <parent link="${ns}_hand"/>
      <child link="${ns}_finger_right_link"/>
      <origin xyz="0 0.009 +0.0590" rpy="0 0 0"/>
      <axis xyz="0 +1 0"/>
      <limit lower="-0.1" upper="0.15" effort="1000000" velocity="1000000"/>
    </joint>
    <link name="${ns}_finger_right_link">
      <visual>
        <origin xyz="0 0 0" rpy="-1.57 0 -1.57"/>
        <geometry>
          <mesh filename="package://assembly_env_description/meshes/gripper2_tip.stl" scale="0.001 0.001 0.001"/>
        </geometry>
        <material name="gray">
          <color rgba="0.25 0.3 0.35 0.75"/>
        </material>
      </visual>
      <collision>
        <origin xyz="0 0 0.01" rpy="0 0 0"/>
        <geometry>

          <box size="0.08 0.0185 0.035"/>

        </geometry>
      </collision>
    </link>
    
    <joint name="${ns}_finger_left_joint" type="prismatic">
      <parent link="${ns}_hand"/>
      <child link="${ns}_finger_left_link"/>
      <origin xyz="0 -0.009 +0.0590" rpy="0 0 0"/>
      <axis xyz="0 -1 0"/>
      <limit lower="-0.1" upper="0.15" effort="1000000" velocity="1000000"/>
    </joint>
    <link name="${ns}_finger_left_link">
      <visual>
        <origin xyz="0 0 0" rpy="-1.57 0 -1.57"/>
        <geometry>
          <mesh filename="package://assembly_env_description/meshes/gripper2_tip.stl" scale="0.001 0.001 0.001"/>
        </geometry>
        <material name="gray">
          <color rgba="0.25 0.3 0.35 0.75"/>
        </material>
      </visual>
      <collision>
        <origin xyz="0 0 0.01" rpy="0 0 0"/>
        <geometry>

          <box size="0.08 0.0185 0.035"/>

        </geometry>
      </collision>
    </link>

  </xacro:macro>
</robot>
