<?xml version="1.0" encoding="utf-8"?>
<!-- =================================================================================== -->
<!-- |    This document was autogenerated by xacro from dyros_assembly_gripper.urdf.xacro | -->
<!-- |    EDITING THIS FILE BY HAND IS NOT RECOMMENDED                                 | -->
<!-- =================================================================================== -->
<robot name="dyros_assembly_gripper">
  <link name="panda_right_hand">
    <visual>
      <origin rpy="-1.57 0 -1.57" xyz="0 0 0"/>
      <geometry>
        <mesh filename="package://assembly_env_description/meshes/gripper_base.stl" scale="0.001 0.001 0.001"/>
      </geometry>
      <material name="blue">
        <color rgba="0 0 0.8 1"/>
      </material>
    </visual>
    <inertial>
      <mass value="0.55"/>
      <inertia ixx="0.0014362" ixy="0.000013" ixz="-0.0000278" iyy="0.00077" iyz="-0.0000897" izz="0.001039"/>
    </inertial>
  </link>
  <joint name="panda_right_finger_joint" type="prismatic">
    <parent link="panda_right_hand"/>
    <child link="panda_right_finger"/>
    <origin rpy="0 0 0" xyz="-0.01175 -0.0165 +0.0685"/>
    <axis xyz="0 1 0"/>
    <limit effort="1000000" lower="0.0" upper="0.15" velocity="1000000"/>
  </joint>
  <link name="panda_right_finger">
    <visual>
      <origin rpy="-1.57 0 -1.57" xyz="0 0 0"/>
      <geometry>
        <mesh filename="package://assembly_env_description/meshes/gripper_moving_tip.stl" scale="0.001 0.001 0.001"/>
      </geometry>
      <material name="green">
        <color rgba="0 0.8 0 1"/>
      </material>
    </visual>
  </link>
</robot>
